Failed to import the site module
Traceback (most recent call last):
  File "/usr/lib/python3.6/site.py", line 570, in <module>
    main()
  File "/usr/lib/python3.6/site.py", line 553, in main
    known_paths = venv(known_paths)
  File "/usr/lib/python3.6/site.py", line 490, in venv
    addsitepackages(known_paths, [sys.prefix])
  File "/usr/lib/python3.6/site.py", line 345, in addsitepackages
    addsitedir(sitedir, known_paths)
  File "/usr/lib/python3.6/site.py", line 213, in addsitedir
    addpackage(sitedir, name, known_paths)
  File "/usr/lib/python3.6/site.py", line 174, in addpackage
    exec(line)
  File "<string>", line 1, in <module>
  File "/usr/lib/python3.6/importlib/util.py", line 13, in <module>
    from contextlib import contextmanager
  File "/usr/lib/python3.6/contextlib.py", line 206, in <module>
    class redirect_stdout(_RedirectStream):
  File "/usr/lib/python3.6/abc.py", line 133, in __new__
    cls = super().__new__(mcls, name, bases, namespace, **kwargs)
KeyboardInterrupt
Command exited with non-zero status 1
0.02user 0.00system 0:00.02elapsed 100%CPU (0avgtext+0avgdata 9348maxresident)k
32inputs+8outputs (0major+1035minor)pagefaults 0swaps
Failed to import the site module
Traceback (most recent call last):
  File "/usr/lib/python3.6/site.py", line 79, in <module>
    import os
  File "/usr/lib/python3.6/os.py", line 26, in <module>
    import sys, errno
KeyboardInterrupt
Command exited with non-zero status 1
0.00user 0.01system 0:00.02elapsed 90%CPU (0avgtext+0avgdata 7968maxresident)k
0inputs+0outputs (0major+715minor)pagefaults 0swaps
Failed to import the site module
Traceback (most recent call last):
  File "/usr/lib/python3.6/site.py", line 79, in <module>
    import os
  File "/usr/lib/python3.6/os.py", line 652, in <module>
    from _collections_abc import MutableMapping
  File "/usr/lib/python3.6/_collections_abc.py", line 928, in <module>
    Sequence.register(range)
  File "/usr/lib/python3.6/abc.py", line 158, in register
    if issubclass(subclass, cls):
  File "/usr/lib/python3.6/abc.py", line 196, in __subclasscheck__
    def __subclasscheck__(cls, subclass):
KeyboardInterrupt
Command exited with non-zero status 1
0.02user 0.00system 0:00.02elapsed 100%CPU (0avgtext+0avgdata 8452maxresident)k
0inputs+0outputs (0major+825minor)pagefaults 0swaps
Traceback (most recent call last):
  File "third_party/my_run_tag.py", line 30, in <module>
    import numpy as np
  File "/home/abhijeet/rohan/venvs/cloud-emea-copy/lib/python3.6/site-packages/numpy/__init__.py", line 140, in <module>
    from . import core
  File "/home/abhijeet/rohan/venvs/cloud-emea-copy/lib/python3.6/site-packages/numpy/core/__init__.py", line 22, in <module>
    from . import multiarray
  File "/home/abhijeet/rohan/venvs/cloud-emea-copy/lib/python3.6/site-packages/numpy/core/multiarray.py", line 12, in <module>
    from . import overrides
  File "/home/abhijeet/rohan/venvs/cloud-emea-copy/lib/python3.6/site-packages/numpy/core/overrides.py", line 9, in <module>
    from numpy.compat._inspect import getargspec
  File "/home/abhijeet/rohan/venvs/cloud-emea-copy/lib/python3.6/site-packages/numpy/compat/__init__.py", line 12, in <module>
    from . import py3k
  File "/home/abhijeet/rohan/venvs/cloud-emea-copy/lib/python3.6/site-packages/numpy/compat/py3k.py", line 21, in <module>
    from pathlib import Path, PurePath
  File "<frozen importlib._bootstrap>", line 971, in _find_and_load
  File "<frozen importlib._bootstrap>", line 955, in _find_and_load_unlocked
  File "<frozen importlib._bootstrap>", line 665, in _load_unlocked
  File "<frozen importlib._bootstrap_external>", line 674, in exec_module
  File "<frozen importlib._bootstrap_external>", line 779, in get_code
  File "<frozen importlib._bootstrap_external>", line 487, in _compile_bytecode
KeyboardInterrupt
Command exited with non-zero status 1
0.76user 1.05system 0:00.10elapsed 1698%CPU (0avgtext+0avgdata 20164maxresident)k
0inputs+8outputs (0major+3034minor)pagefaults 0swaps
PyTorch version 1.10.1+cu102 available.
01/13/2022 16:53:20 - INFO - root -   Input args: ModelArguments(model_name_or_path='bert-base-multilingual-cased', model_type='bert', config_name=None, tokenizer_name=None, cache_dir=None, labels='/home/abhijeet/rohan/cloud-emea-copy/data//udpos/udpos_processed_maxlen128//labels.txt', data_dir='/home/abhijeet/rohan/cloud-emea-copy/data//udpos/udpos_processed_maxlen128/', output_dir='/home/abhijeet/rohan/cloud-emea-copy/outputs//udpos/my-bert-base-multilingual-cased-MaxLen128_udpos_ht/', max_seq_length=128, do_train=False, do_eval=False, do_predict=True, do_adapter_predict=False, do_predict_dev=False, do_predict_train=False, init_checkpoint=None, evaluate_during_training=False, do_lower_case=False, few_shot=-1, per_gpu_train_batch_size=8, per_gpu_eval_batch_size=32, gradient_accumulation_steps=4, learning_rate=5e-05, weight_decay=0.0, adam_epsilon=1e-08, max_grad_norm=1.0, num_train_epochs=50.0, max_steps=-1, save_steps=1000, warmup_steps=0, logging_steps=50, save_only_best_checkpoint=True, eval_all_checkpoints=True, no_cuda=False, overwrite_output_dir=True, overwrite_cache=False, seed=2, fp16=False, fp16_opt_level='O1', local_rank=-1, server_ip='', server_port='', predict_langs='wo', train_langs='en', log_file='/home/abhijeet/rohan/cloud-emea-copy/outputs//udpos/my-bert-base-multilingual-cased-MaxLen128_udpos_ht//train_en.log', eval_patience=-1, bpe_dropout=0, do_save_adapter_fusions=False, task_name='udpos', predict_task_adapter='output/udpos/my-bert-base-multilingual-cased-LR1e-4-epoch50-MaxLen128-TrainLangen_en_s2/checkpoint-best/udpos/', predict_lang_adapter=None, test_adapter=True, adapter_weight=None, lang_to_vec=None, calc_weight_step=0, predict_save_prefix='', en_weight=None, temperature=1.0, get_attr=False, topk=1, task='udpos')
01/13/2022 16:53:20 - WARNING - __main__ -   Process rank: -1, device: cuda, n_gpu: 1, distributed training: False, 16-bits training: False
01/13/2022 16:53:20 - INFO - __main__ -   Seed = 2
01/13/2022 16:53:20 - INFO - root -   save model
01/13/2022 16:53:20 - INFO - __main__ -   Training/evaluation parameters ModelArguments(model_name_or_path='bert-base-multilingual-cased', model_type='bert', config_name=None, tokenizer_name=None, cache_dir=None, labels='/home/abhijeet/rohan/cloud-emea-copy/data//udpos/udpos_processed_maxlen128//labels.txt', data_dir='/home/abhijeet/rohan/cloud-emea-copy/data//udpos/udpos_processed_maxlen128/', output_dir='/home/abhijeet/rohan/cloud-emea-copy/outputs//udpos/my-bert-base-multilingual-cased-MaxLen128_udpos_ht/', max_seq_length=128, do_train=False, do_eval=False, do_predict=True, do_adapter_predict=False, do_predict_dev=False, do_predict_train=False, init_checkpoint=None, evaluate_during_training=False, do_lower_case=False, few_shot=-1, per_gpu_train_batch_size=8, per_gpu_eval_batch_size=32, gradient_accumulation_steps=4, learning_rate=5e-05, weight_decay=0.0, adam_epsilon=1e-08, max_grad_norm=1.0, num_train_epochs=50.0, max_steps=-1, save_steps=1000, warmup_steps=0, logging_steps=50, save_only_best_checkpoint=True, eval_all_checkpoints=True, no_cuda=False, overwrite_output_dir=True, overwrite_cache=False, seed=2, fp16=False, fp16_opt_level='O1', local_rank=-1, server_ip='', server_port='', predict_langs='wo', train_langs='en', log_file='/home/abhijeet/rohan/cloud-emea-copy/outputs//udpos/my-bert-base-multilingual-cased-MaxLen128_udpos_ht//train_en.log', eval_patience=-1, bpe_dropout=0, do_save_adapter_fusions=False, task_name='udpos', predict_task_adapter='output/udpos/my-bert-base-multilingual-cased-LR1e-4-epoch50-MaxLen128-TrainLangen_en_s2/checkpoint-best/udpos/', predict_lang_adapter=None, test_adapter=True, adapter_weight=None, lang_to_vec=None, calc_weight_step=0, predict_save_prefix='', en_weight=None, temperature=1.0, get_attr=False, topk=1, task='udpos')
01/13/2022 16:53:20 - INFO - __main__ -   Loading pretrained model and tokenizer


During handling of the above exception, another exception occurred:

Traceback (most recent call last):
  File "third_party/my_run_tag.py", line 1123, in <module>
    main()
  File "third_party/my_run_tag.py", line 1050, in main
    model, tokenizer, lang2id = load_model(args, num_labels)
  File "third_party/my_run_tag.py", line 781, in load_model
    cache_dir=args.cache_dir,
  File "/home/abhijeet/rohan/cloud-emea-copy/src/transformers/configuration_auto.py", line 333, in from_pretrained
    config_dict, _ = PretrainedConfig.get_config_dict(pretrained_model_name_or_path, **kwargs)
  File "/home/abhijeet/rohan/cloud-emea-copy/src/transformers/configuration_utils.py", line 389, in get_config_dict
    local_files_only=local_files_only,
  File "/home/abhijeet/rohan/cloud-emea-copy/src/transformers/file_utils.py", line 955, in cached_path
    local_files_only=local_files_only,
  File "/home/abhijeet/rohan/cloud-emea-copy/src/transformers/file_utils.py", line 1075, in get_from_cache
    r = requests.head(url, headers=headers, allow_redirects=False, proxies=proxies, timeout=etag_timeout)
  File "/home/abhijeet/rohan/venvs/cloud-emea-copy/lib/python3.6/site-packages/requests/api.py", line 102, in head
    return request('head', url, **kwargs)
  File "/home/abhijeet/rohan/venvs/cloud-emea-copy/lib/python3.6/site-packages/requests/api.py", line 61, in request
    return session.request(method=method, url=url, **kwargs)
  File "/home/abhijeet/rohan/venvs/cloud-emea-copy/lib/python3.6/site-packages/requests/sessions.py", line 415, in __exit__
    self.close()
  File "/home/abhijeet/rohan/venvs/cloud-emea-copy/lib/python3.6/site-packages/requests/sessions.py", line 737, in close
    v.close()
  File "/home/abhijeet/rohan/venvs/cloud-emea-copy/lib/python3.6/site-packages/requests/adapters.py", line 326, in close
    self.poolmanager.clear()
  File "/home/abhijeet/rohan/venvs/cloud-emea-copy/lib/python3.6/site-packages/urllib3/poolmanager.py", line 222, in clear
    self.pools.clear()
  File "/home/abhijeet/rohan/venvs/cloud-emea-copy/lib/python3.6/site-packages/urllib3/_collections.py", line 93, in clear
    with self.lock:
KeyboardInterrupt
Command terminated by signal 2
6.22user 7.91system 0:04.41elapsed 320%CPU (0avgtext+0avgdata 294892maxresident)k
64inputs+24outputs (0major+51204minor)pagefaults 0swaps
Failed to import the site module
Traceback (most recent call last):
  File "/usr/lib/python3.6/site.py", line 79, in <module>
    import os
  File "/usr/lib/python3.6/os.py", line 57, in <module>
    import posixpath as path
  File "/usr/lib/python3.6/posixpath.py", line 28, in <module>
    import genericpath
  File "<frozen importlib._bootstrap>", line 971, in _find_and_load
  File "<frozen importlib._bootstrap>", line 951, in _find_and_load_unlocked
  File "<frozen importlib._bootstrap>", line 886, in _find_spec
  File "<frozen importlib._bootstrap>", line 843, in __enter__
KeyboardInterrupt
Command exited with non-zero status 1
0.02user 0.00system 0:00.02elapsed 100%CPU (0avgtext+0avgdata 8148maxresident)k
0inputs+0outputs (0major+766minor)pagefaults 0swaps
