Failed to import the site module
Traceback (most recent call last):
  File "/usr/lib/python3.6/site.py", line 79, in <module>
    import os
  File "/usr/lib/python3.6/os.py", line 57, in <module>
    import posixpath as path
  File "/usr/lib/python3.6/posixpath.py", line 28, in <module>
    import genericpath
  File "<frozen importlib._bootstrap>", line 971, in _find_and_load
  File "<frozen importlib._bootstrap>", line 955, in _find_and_load_unlocked
  File "<frozen importlib._bootstrap>", line 665, in _load_unlocked
  File "<frozen importlib._bootstrap_external>", line 674, in exec_module
  File "<frozen importlib._bootstrap_external>", line 764, in get_code
  File "<frozen importlib._bootstrap_external>", line 833, in get_data
KeyboardInterrupt
Command exited with non-zero status 1
0.01user 0.00system 0:00.02elapsed 100%CPU (0avgtext+0avgdata 8188maxresident)k
0inputs+8outputs (0major+766minor)pagefaults 0swaps
Traceback (most recent call last):
  File "third_party/my_run_tag.py", line 17, in <module>
    """Fine-tuning models for NER and POS tagging."""
KeyboardInterrupt
Command exited with non-zero status 1
0.03user 0.01system 0:00.04elapsed 97%CPU (0avgtext+0avgdata 12456maxresident)k
0inputs+0outputs (0major+1869minor)pagefaults 0swaps
Command terminated by signal 2
0.00user 0.00system 0:00.01elapsed 90%CPU (0avgtext+0avgdata 7028maxresident)k
0inputs+0outputs (0major+562minor)pagefaults 0swaps
Failed to import the site module
Traceback (most recent call last):
  File "/usr/lib/python3.6/site.py", line 79, in <module>
  File "/usr/lib/python3.6/os.py", line 27, in <module>
  File "<frozen importlib._bootstrap>", line 971, in _find_and_load
  File "<frozen importlib._bootstrap>", line 951, in _find_and_load_unlocked
  File "<frozen importlib._bootstrap>", line 894, in _find_spec
  File "<frozen importlib._bootstrap_external>", line 1157, in find_spec
  File "<frozen importlib._bootstrap_external>", line 1129, in _get_spec
  File "<frozen importlib._bootstrap_external>", line 1268, in find_spec
KeyboardInterrupt
Command exited with non-zero status 1
0.02user 0.00system 0:00.02elapsed 100%CPU (0avgtext+0avgdata 7892maxresident)k
0inputs+8outputs (0major+713minor)pagefaults 0swaps
Traceback (most recent call last):
  File "/home/abhijeet/rohan/venvs/cloud-emea-copy/lib/python3.6/site-packages/numpy/compat/py3k.py", line 28, in <module>
ModuleNotFoundError: No module named 'pickle5'

During handling of the above exception, another exception occurred:

Traceback (most recent call last):
  File "third_party/my_run_tag.py", line 30, in <module>
    import numpy as np
  File "/home/abhijeet/rohan/venvs/cloud-emea-copy/lib/python3.6/site-packages/numpy/__init__.py", line 140, in <module>
    from . import core
  File "/home/abhijeet/rohan/venvs/cloud-emea-copy/lib/python3.6/site-packages/numpy/core/__init__.py", line 22, in <module>
    from . import multiarray
  File "/home/abhijeet/rohan/venvs/cloud-emea-copy/lib/python3.6/site-packages/numpy/core/multiarray.py", line 12, in <module>
    from . import overrides
  File "/home/abhijeet/rohan/venvs/cloud-emea-copy/lib/python3.6/site-packages/numpy/core/overrides.py", line 9, in <module>
    from numpy.compat._inspect import getargspec
  File "/home/abhijeet/rohan/venvs/cloud-emea-copy/lib/python3.6/site-packages/numpy/compat/__init__.py", line 12, in <module>
    from . import py3k
  File "/home/abhijeet/rohan/venvs/cloud-emea-copy/lib/python3.6/site-packages/numpy/compat/py3k.py", line 30, in <module>
    import pickle
  File "/usr/lib/python3.6/pickle.py", line 37, in <module>
    import _compat_pickle
  File "<frozen importlib._bootstrap>", line 971, in _find_and_load
  File "<frozen importlib._bootstrap>", line 936, in _find_and_load_unlocked
KeyboardInterrupt
Command exited with non-zero status 1
0.90user 1.22system 0:00.11elapsed 1783%CPU (0avgtext+0avgdata 20252maxresident)k
96inputs+0outputs (0major+3122minor)pagefaults 0swaps
Traceback (most recent call last):
  File "third_party/my_run_tag.py", line 30, in <module>
    import numpy as np
  File "/home/abhijeet/rohan/venvs/cloud-emea-copy/lib/python3.6/site-packages/numpy/__init__.py", line 140, in <module>
    from . import core
  File "/home/abhijeet/rohan/venvs/cloud-emea-copy/lib/python3.6/site-packages/numpy/core/__init__.py", line 70, in <module>
  File "/home/abhijeet/rohan/venvs/cloud-emea-copy/lib/python3.6/site-packages/numpy/core/numerictypes.py", line 83, in <module>
    import numbers
  File "/usr/lib/python3.6/numbers.py", line 147, in <module>
  File "/usr/lib/python3.6/abc.py", line 136, in __new__
    for name, value in namespace.items()
  File "/usr/lib/python3.6/abc.py", line 137, in <setcomp>
    if getattr(value, "__isabstractmethod__", False)}
KeyboardInterrupt
Command exited with non-zero status 1
0.85user 0.96system 0:00.10elapsed 1762%CPU (0avgtext+0avgdata 20728maxresident)k
24inputs+8outputs (0major+3165minor)pagefaults 0swaps
