Failed to import the site module
Traceback (most recent call last):
  File "/usr/lib/python3.6/site.py", line 570, in <module>
    main()
  File "/usr/lib/python3.6/site.py", line 553, in main
    known_paths = venv(known_paths)
  File "/usr/lib/python3.6/site.py", line 490, in venv
    addsitepackages(known_paths, [sys.prefix])
  File "/usr/lib/python3.6/site.py", line 345, in addsitepackages
    addsitedir(sitedir, known_paths)
  File "/usr/lib/python3.6/site.py", line 213, in addsitedir
    addpackage(sitedir, name, known_paths)
  File "/usr/lib/python3.6/site.py", line 174, in addpackage
    exec(line)
  File "<string>", line 1, in <module>
  File "/usr/lib/python3.6/types.py", line 171, in <module>
    import functools as _functools
  File "/usr/lib/python3.6/functools.py", line 21, in <module>
    from collections import namedtuple
  File "<frozen importlib._bootstrap>", line 971, in _find_and_load
  File "<frozen importlib._bootstrap>", line 955, in _find_and_load_unlocked
  File "<frozen importlib._bootstrap>", line 665, in _load_unlocked
  File "<frozen importlib._bootstrap_external>", line 674, in exec_module
  File "<frozen importlib._bootstrap_external>", line 779, in get_code
  File "<frozen importlib._bootstrap_external>", line 487, in _compile_bytecode
KeyboardInterrupt
Command exited with non-zero status 1
0.01user 0.01system 0:00.02elapsed 100%CPU (0avgtext+0avgdata 8828maxresident)k
0inputs+8outputs (0major+934minor)pagefaults 0swaps
Failed to import the site module
Traceback (most recent call last):
  File "<frozen importlib._bootstrap_external>", line 1096, in _path_importer_cache
KeyError: '/usr/lib/python3.6/importlib'

During handling of the above exception, another exception occurred:

Traceback (most recent call last):
  File "/usr/lib/python3.6/site.py", line 570, in <module>
    main()
  File "/usr/lib/python3.6/site.py", line 553, in main
    known_paths = venv(known_paths)
  File "/usr/lib/python3.6/site.py", line 490, in venv
    addsitepackages(known_paths, [sys.prefix])
  File "/usr/lib/python3.6/site.py", line 345, in addsitepackages
    addsitedir(sitedir, known_paths)
  File "/usr/lib/python3.6/site.py", line 213, in addsitedir
    addpackage(sitedir, name, known_paths)
  File "/usr/lib/python3.6/site.py", line 174, in addpackage
    exec(line)
  File "<string>", line 1, in <module>
  File "<frozen importlib._bootstrap>", line 971, in _find_and_load
  File "<frozen importlib._bootstrap>", line 951, in _find_and_load_unlocked
  File "<frozen importlib._bootstrap>", line 894, in _find_spec
  File "<frozen importlib._bootstrap_external>", line 1157, in find_spec
  File "<frozen importlib._bootstrap_external>", line 1126, in _get_spec
  File "<frozen importlib._bootstrap_external>", line 1098, in _path_importer_cache
  File "<frozen importlib._bootstrap_external>", line 1074, in _path_hooks
  File "<frozen importlib._bootstrap_external>", line 1326, in path_hook_for_FileFinder
  File "<frozen importlib._bootstrap_external>", line 1201, in __init__
KeyboardInterrupt
Command exited with non-zero status 1
0.02user 0.00system 0:00.03elapsed 100%CPU (0avgtext+0avgdata 9192maxresident)k
0inputs+0outputs (0major+1019minor)pagefaults 0swaps
Failed to import the site module
Traceback (most recent call last):
  File "/usr/lib/python3.6/site.py", line 570, in <module>
    main()
  File "/usr/lib/python3.6/site.py", line 553, in main
    known_paths = venv(known_paths)
  File "/usr/lib/python3.6/site.py", line 490, in venv
    addsitepackages(known_paths, [sys.prefix])
  File "/usr/lib/python3.6/site.py", line 345, in addsitepackages
    addsitedir(sitedir, known_paths)
  File "/usr/lib/python3.6/site.py", line 213, in addsitedir
    addpackage(sitedir, name, known_paths)
  File "/usr/lib/python3.6/site.py", line 174, in addpackage
    exec(line)
  File "<string>", line 1, in <module>
  File "/usr/lib/python3.6/types.py", line 171, in <module>
    import functools as _functools
  File "/usr/lib/python3.6/functools.py", line 21, in <module>
    from collections import namedtuple
  File "/usr/lib/python3.6/collections/__init__.py", line 27, in <module>
    from keyword import iskeyword as _iskeyword
  File "<frozen importlib._bootstrap>", line 971, in _find_and_load
  File "<frozen importlib._bootstrap>", line 955, in _find_and_load_unlocked
  File "<frozen importlib._bootstrap>", line 658, in _load_unlocked
  File "<frozen importlib._bootstrap>", line 577, in module_from_spec
  File "<frozen importlib._bootstrap>", line 556, in _init_module_attrs
  File "<frozen importlib._bootstrap>", line 409, in cached
  File "<frozen importlib._bootstrap_external>", line 364, in _get_cached
  File "<frozen importlib._bootstrap_external>", line 290, in cache_from_source
KeyboardInterrupt
Command exited with non-zero status 1
0.02user 0.00system 0:00.03elapsed 96%CPU (0avgtext+0avgdata 9000maxresident)k
0inputs+8outputs (0major+947minor)pagefaults 0swaps
Traceback (most recent call last):
  File "third_party/my_run_tag.py", line 26, in <module>
  File "/home/abhijeet/rohan/venvs/cloud-emea-copy/lib/python3.6/site-packages/dataclasses.py", line 5, in <module>
  File "/usr/lib/python3.6/inspect.py", line 1469, in <module>
  File "/usr/lib/python3.6/collections/__init__.py", line 429, in namedtuple
    exec(class_definition, namespace)
  File "<string>", line 1, in <module>
KeyboardInterrupt
Command exited with non-zero status 1
0.04user 0.01system 0:00.06elapsed 98%CPU (0avgtext+0avgdata 15028maxresident)k
0inputs+8outputs (0major+2467minor)pagefaults 0swaps
Traceback (most recent call last):
  File "third_party/my_run_tag.py", line 30, in <module>
    import numpy as np
  File "/home/abhijeet/rohan/venvs/cloud-emea-copy/lib/python3.6/site-packages/numpy/__init__.py", line 140, in <module>
    from . import core
  File "/home/abhijeet/rohan/venvs/cloud-emea-copy/lib/python3.6/site-packages/numpy/core/__init__.py", line 22, in <module>
    from . import multiarray
  File "/home/abhijeet/rohan/venvs/cloud-emea-copy/lib/python3.6/site-packages/numpy/core/multiarray.py", line 12, in <module>
    from . import overrides
  File "/home/abhijeet/rohan/venvs/cloud-emea-copy/lib/python3.6/site-packages/numpy/core/overrides.py", line 9, in <module>
    from numpy.compat._inspect import getargspec
  File "/home/abhijeet/rohan/venvs/cloud-emea-copy/lib/python3.6/site-packages/numpy/compat/__init__.py", line 12, in <module>
    from . import py3k
  File "/home/abhijeet/rohan/venvs/cloud-emea-copy/lib/python3.6/site-packages/numpy/compat/py3k.py", line 21, in <module>
    from pathlib import Path, PurePath
  File "/usr/lib/python3.6/pathlib.py", line 14, in <module>
    from urllib.parse import quote_from_bytes as urlquote_from_bytes
  File "/usr/lib/python3.6/urllib/parse.py", line 237, in <module>
    _DefragResultBase = namedtuple('DefragResult', 'url fragment')
  File "/usr/lib/python3.6/collections/__init__.py", line 429, in namedtuple
    exec(class_definition, namespace)
  File "<string>", line 1, in <module>
KeyboardInterrupt
Command exited with non-zero status 1
0.94user 1.32system 0:00.12elapsed 1853%CPU (0avgtext+0avgdata 20192maxresident)k
0inputs+0outputs (0major+3049minor)pagefaults 0swaps
Traceback (most recent call last):
  File "/home/abhijeet/rohan/venvs/cloud-emea-copy/lib/python3.6/site-packages/numpy/compat/py3k.py", line 28, in <module>
    import pickle5 as pickle
ModuleNotFoundError: No module named 'pickle5'

During handling of the above exception, another exception occurred:

Traceback (most recent call last):
  File "<frozen importlib._bootstrap>", line 665, in _load_unlocked
  File "<frozen importlib._bootstrap_external>", line 674, in exec_module
  File "<frozen importlib._bootstrap_external>", line 779, in get_code
  File "<frozen importlib._bootstrap_external>", line 487, in _compile_bytecode
KeyboardInterrupt

During handling of the above exception, another exception occurred:

Traceback (most recent call last):
  File "third_party/my_run_tag.py", line 30, in <module>
    import numpy as np
  File "/home/abhijeet/rohan/venvs/cloud-emea-copy/lib/python3.6/site-packages/numpy/__init__.py", line 140, in <module>
    from . import core
  File "/home/abhijeet/rohan/venvs/cloud-emea-copy/lib/python3.6/site-packages/numpy/core/__init__.py", line 22, in <module>
    from . import multiarray
  File "/home/abhijeet/rohan/venvs/cloud-emea-copy/lib/python3.6/site-packages/numpy/core/multiarray.py", line 12, in <module>
    from . import overrides
  File "/home/abhijeet/rohan/venvs/cloud-emea-copy/lib/python3.6/site-packages/numpy/core/overrides.py", line 9, in <module>
    from numpy.compat._inspect import getargspec
  File "/home/abhijeet/rohan/venvs/cloud-emea-copy/lib/python3.6/site-packages/numpy/compat/__init__.py", line 12, in <module>
    from . import py3k
  File "/home/abhijeet/rohan/venvs/cloud-emea-copy/lib/python3.6/site-packages/numpy/compat/py3k.py", line 30, in <module>
    import pickle
  File "<frozen importlib._bootstrap>", line 971, in _find_and_load
  File "<frozen importlib._bootstrap>", line 955, in _find_and_load_unlocked
  File "<frozen importlib._bootstrap>", line 665, in _load_unlocked
KeyboardInterrupt
Command exited with non-zero status 1
0.82user 1.05system 0:00.10elapsed 1861%CPU (0avgtext+0avgdata 20252maxresident)k
0inputs+8outputs (0major+3089minor)pagefaults 0swaps
