Failed to import the site module
Traceback (most recent call last):
  File "/usr/lib/python3.6/site.py", line 570, in <module>
    main()
  File "/usr/lib/python3.6/site.py", line 553, in main
    known_paths = venv(known_paths)
  File "/usr/lib/python3.6/site.py", line 490, in venv
    addsitepackages(known_paths, [sys.prefix])
  File "/usr/lib/python3.6/site.py", line 345, in addsitepackages
    addsitedir(sitedir, known_paths)
  File "/usr/lib/python3.6/site.py", line 213, in addsitedir
    addpackage(sitedir, name, known_paths)
  File "/usr/lib/python3.6/site.py", line 174, in addpackage
    exec(line)
  File "<string>", line 1, in <module>
  File "/usr/lib/python3.6/importlib/util.py", line 2, in <module>
    from . import abc
  File "/usr/lib/python3.6/importlib/abc.py", line 186, in <module>
    class InspectLoader(Loader):
  File "/usr/lib/python3.6/abc.py", line 133, in __new__
    cls = super().__new__(mcls, name, bases, namespace, **kwargs)
KeyboardInterrupt
Command exited with non-zero status 1
0.02user 0.00system 0:00.03elapsed 100%CPU (0avgtext+0avgdata 9240maxresident)k
0inputs+8outputs (0major+1021minor)pagefaults 0swaps
Failed to import the site module
Traceback (most recent call last):
  File "/usr/lib/python3.6/site.py", line 570, in <module>
    main()
  File "/usr/lib/python3.6/site.py", line 553, in main
    known_paths = venv(known_paths)
  File "/usr/lib/python3.6/site.py", line 490, in venv
    addsitepackages(known_paths, [sys.prefix])
  File "/usr/lib/python3.6/site.py", line 345, in addsitepackages
    addsitedir(sitedir, known_paths)
  File "/usr/lib/python3.6/site.py", line 213, in addsitedir
    addpackage(sitedir, name, known_paths)
  File "/usr/lib/python3.6/site.py", line 174, in addpackage
    exec(line)
  File "<string>", line 1, in <module>
  File "/usr/lib/python3.6/types.py", line 171, in <module>
    import functools as _functools
  File "/usr/lib/python3.6/functools.py", line 21, in <module>
    from collections import namedtuple
  File "/usr/lib/python3.6/collections/__init__.py", line 32, in <module>
    from reprlib import recursive_repr as _recursive_repr
  File "<frozen importlib._bootstrap>", line 971, in _find_and_load
  File "<frozen importlib._bootstrap>", line 951, in _find_and_load_unlocked
  File "<frozen importlib._bootstrap>", line 894, in _find_spec
  File "<frozen importlib._bootstrap_external>", line 1157, in find_spec
  File "<frozen importlib._bootstrap_external>", line 1129, in _get_spec
  File "<frozen importlib._bootstrap_external>", line 1241, in find_spec
  File "<frozen importlib._bootstrap_external>", line 82, in _path_stat
KeyboardInterrupt
Command exited with non-zero status 1
0.02user 0.00system 0:00.02elapsed 100%CPU (0avgtext+0avgdata 9064maxresident)k
0inputs+0outputs (0major+958minor)pagefaults 0swaps
Failed to import the site module
Traceback (most recent call last):
  File "/usr/lib/python3.6/site.py", line 79, in <module>
    import os
  File "/usr/lib/python3.6/os.py", line 652, in <module>
    from _collections_abc import MutableMapping
  File "/usr/lib/python3.6/_collections_abc.py", line 284, in <module>
    Iterator.register(list_reverseiterator)
  File "/usr/lib/python3.6/abc.py", line 158, in register
    if issubclass(subclass, cls):
  File "/usr/lib/python3.6/abc.py", line 209, in __subclasscheck__
    ok = cls.__subclasshook__(subclass)
  File "/usr/lib/python3.6/_collections_abc.py", line 274, in __subclasshook__
    return _check_methods(C, '__iter__', '__next__')
  File "/usr/lib/python3.6/_collections_abc.py", line 73, in _check_methods
    mro = C.__mro__
KeyboardInterrupt
Command exited with non-zero status 1
0.02user 0.00system 0:00.02elapsed 100%CPU (0avgtext+0avgdata 8380maxresident)k
0inputs+0outputs (0major+808minor)pagefaults 0swaps
Traceback (most recent call last):
  File "/home/abhijeet/rohan/venvs/cloud-emea-copy/lib/python3.6/site-packages/numpy/core/__init__.py", line 22, in <module>
    from . import multiarray
  File "/home/abhijeet/rohan/venvs/cloud-emea-copy/lib/python3.6/site-packages/numpy/core/multiarray.py", line 12, in <module>
    from . import overrides
  File "/home/abhijeet/rohan/venvs/cloud-emea-copy/lib/python3.6/site-packages/numpy/core/overrides.py", line 7, in <module>
    from numpy.core._multiarray_umath import (
ImportError: PyCapsule_Import could not import module "datetime"

During handling of the above exception, another exception occurred:

Traceback (most recent call last):
  File "third_party/my_run_tag.py", line 30, in <module>
    import numpy as np
  File "/home/abhijeet/rohan/venvs/cloud-emea-copy/lib/python3.6/site-packages/numpy/__init__.py", line 140, in <module>
    from . import core
  File "/home/abhijeet/rohan/venvs/cloud-emea-copy/lib/python3.6/site-packages/numpy/core/__init__.py", line 48, in <module>
    raise ImportError(msg)
ImportError: 

IMPORTANT: PLEASE READ THIS FOR ADVICE ON HOW TO SOLVE THIS ISSUE!

Importing the numpy C-extensions failed. This error can happen for
many reasons, often due to issues with your setup or how NumPy was
installed.

We have compiled some common reasons and troubleshooting tips at:

    https://numpy.org/devdocs/user/troubleshooting-importerror.html

Please note and check the following:

  * The Python version is: Python3.6 from "/home/abhijeet/rohan/venvs/cloud-emea-copy/bin/python"
  * The NumPy version is: "1.19.5"

and make sure that they are the versions you expect.
Please carefully study the documentation linked above for further help.

Original error was: PyCapsule_Import could not import module "datetime"

Command exited with non-zero status 1
0.50user 0.66system 0:00.09elapsed 1265%CPU (0avgtext+0avgdata 19064maxresident)k
0inputs+16outputs (0major+2899minor)pagefaults 0swaps
Command terminated by signal 2
0.00user 0.00system 0:00.00elapsed 80%CPU (0avgtext+0avgdata 6236maxresident)k
0inputs+0outputs (0major+444minor)pagefaults 0swaps
Failed to import the site module
Traceback (most recent call last):
  File "/usr/lib/python3.6/os.py", line 42, in _get_exports_list
AttributeError: module 'posix' has no attribute '__all__'

During handling of the above exception, another exception occurred:

Traceback (most recent call last):
  File "/usr/lib/python3.6/site.py", line 79, in <module>
    import os
  File "/usr/lib/python3.6/os.py", line 65, in <module>
    __all__.extend(_get_exports_list(posix))
  File "/usr/lib/python3.6/os.py", line 44, in _get_exports_list
    return [n for n in dir(module) if n[0] != '_']
  File "/usr/lib/python3.6/os.py", line 44, in <listcomp>
    return [n for n in dir(module) if n[0] != '_']
KeyboardInterrupt
Command exited with non-zero status 1
0.01user 0.00system 0:00.01elapsed 100%CPU (0avgtext+0avgdata 8356maxresident)k
0inputs+0outputs (0major+777minor)pagefaults 0swaps
