Failed to import the site module
Traceback (most recent call last):
  File "/usr/lib/python3.6/site.py", line 570, in <module>
    main()
  File "/usr/lib/python3.6/site.py", line 551, in main
    abs_paths()
  File "/usr/lib/python3.6/site.py", line 116, in abs_paths
    m.__cached__ = os.path.abspath(m.__cached__)
  File "/usr/lib/python3.6/posixpath.py", line 385, in abspath
    return normpath(path)
  File "/usr/lib/python3.6/posixpath.py", line 361, in normpath
    for comp in comps:
KeyboardInterrupt
Command exited with non-zero status 1
0.01user 0.00system 0:00.02elapsed 95%CPU (0avgtext+0avgdata 8476maxresident)k
0inputs+8outputs (0major+833minor)pagefaults 0swaps
Failed to import the site module
Traceback (most recent call last):
  File "/usr/lib/python3.6/site.py", line 570, in <module>
    main()
  File "/usr/lib/python3.6/site.py", line 553, in main
    known_paths = venv(known_paths)
  File "/usr/lib/python3.6/site.py", line 490, in venv
    addsitepackages(known_paths, [sys.prefix])
  File "/usr/lib/python3.6/site.py", line 345, in addsitepackages
    addsitedir(sitedir, known_paths)
  File "/usr/lib/python3.6/site.py", line 213, in addsitedir
    addpackage(sitedir, name, known_paths)
  File "/usr/lib/python3.6/site.py", line 174, in addpackage
    exec(line)
  File "<string>", line 1, in <module>
KeyboardInterrupt
Command exited with non-zero status 1
0.02user 0.00system 0:00.02elapsed 96%CPU (0avgtext+0avgdata 8620maxresident)k
0inputs+0outputs (0major+860minor)pagefaults 0swaps
Traceback (most recent call last):
  File "third_party/my_run_tag.py", line 17, in <module>
    """Fine-tuning models for NER and POS tagging."""
KeyboardInterrupt
Command exited with non-zero status 1
0.03user 0.00system 0:00.03elapsed 97%CPU (0avgtext+0avgdata 12512maxresident)k
0inputs+0outputs (0major+1870minor)pagefaults 0swaps
Traceback (most recent call last):
  File "third_party/my_run_tag.py", line 23, in <module>
    import logging
  File "/usr/lib/python3.6/logging/__init__.py", line 26, in <module>
    import sys, os, time, io, traceback, warnings, weakref, collections
  File "/usr/lib/python3.6/traceback.py", line 5, in <module>
    import linecache
  File "/usr/lib/python3.6/linecache.py", line 11, in <module>
    import tokenize
  File "/usr/lib/python3.6/tokenize.py", line 35, in <module>
    from token import *
  File "<frozen importlib._bootstrap>", line 971, in _find_and_load
  File "<frozen importlib._bootstrap>", line 951, in _find_and_load_unlocked

Command exited with non-zero status 1
0.03user 0.01system 0:00.04elapsed 100%CPU (0avgtext+0avgdata 12480maxresident)k
0inputs+8outputs (0major+2023minor)pagefaults 0swaps
Traceback (most recent call last):
  File "<frozen importlib._bootstrap>", line 665, in _load_unlocked
  File "<frozen importlib._bootstrap_external>", line 678, in exec_module
  File "<frozen importlib._bootstrap>", line 219, in _call_with_frames_removed
  File "/usr/lib/python3.6/pathlib.py", line 14, in <module>
    from urllib.parse import quote_from_bytes as urlquote_from_bytes
  File "<frozen importlib._bootstrap>", line 971, in _find_and_load
  File "<frozen importlib._bootstrap>", line 955, in _find_and_load_unlocked
  File "<frozen importlib._bootstrap>", line 665, in _load_unlocked
  File "<frozen importlib._bootstrap_external>", line 674, in exec_module
  File "<frozen importlib._bootstrap_external>", line 779, in get_code
  File "<frozen importlib._bootstrap_external>", line 487, in _compile_bytecode
KeyboardInterrupt

During handling of the above exception, another exception occurred:

Traceback (most recent call last):
  File "/home/abhijeet/rohan/venvs/cloud-emea-copy/lib/python3.6/site-packages/numpy/core/__init__.py", line 22, in <module>
    from . import multiarray
  File "/home/abhijeet/rohan/venvs/cloud-emea-copy/lib/python3.6/site-packages/numpy/core/multiarray.py", line 12, in <module>
    from . import overrides
  File "/home/abhijeet/rohan/venvs/cloud-emea-copy/lib/python3.6/site-packages/numpy/core/overrides.py", line 9, in <module>
    from numpy.compat._inspect import getargspec
  File "/home/abhijeet/rohan/venvs/cloud-emea-copy/lib/python3.6/site-packages/numpy/compat/__init__.py", line 12, in <module>
    from . import py3k
  File "/home/abhijeet/rohan/venvs/cloud-emea-copy/lib/python3.6/site-packages/numpy/compat/py3k.py", line 21, in <module>
    from pathlib import Path, PurePath
  File "<frozen importlib._bootstrap>", line 971, in _find_and_load
  File "<frozen importlib._bootstrap>", line 955, in _find_and_load_unlocked
  File "<frozen importlib._bootstrap>", line 665, in _load_unlocked
  File "<frozen importlib._bootstrap>", line 319, in __exit__
KeyboardInterrupt

During handling of the above exception, another exception occurred:

Traceback (most recent call last):
  File "third_party/my_run_tag.py", line 30, in <module>
    import numpy as np
  File "/home/abhijeet/rohan/venvs/cloud-emea-copy/lib/python3.6/site-packages/numpy/__init__.py", line 140, in <module>
    from . import core
  File "/home/abhijeet/rohan/venvs/cloud-emea-copy/lib/python3.6/site-packages/numpy/core/__init__.py", line 51, in <module>
    del os.environ[envkey]
  File "/usr/lib/python3.6/os.py", line 678, in __delitem__
    def __delitem__(self, key):
KeyboardInterrupt
Command exited with non-zero status 1
0.83user 1.15system 0:00.11elapsed 1683%CPU (0avgtext+0avgdata 20164maxresident)k
0inputs+8outputs (0major+3031minor)pagefaults 0swaps
Traceback (most recent call last):
  File "third_party/my_run_tag.py", line 30, in <module>
    import numpy as np
  File "/home/abhijeet/rohan/venvs/cloud-emea-copy/lib/python3.6/site-packages/numpy/__init__.py", line 140, in <module>
    from . import core
  File "/home/abhijeet/rohan/venvs/cloud-emea-copy/lib/python3.6/site-packages/numpy/core/__init__.py", line 22, in <module>
    from . import multiarray
  File "/home/abhijeet/rohan/venvs/cloud-emea-copy/lib/python3.6/site-packages/numpy/core/multiarray.py", line 12, in <module>
    from . import overrides
  File "/home/abhijeet/rohan/venvs/cloud-emea-copy/lib/python3.6/site-packages/numpy/core/overrides.py", line 9, in <module>
    from numpy.compat._inspect import getargspec
  File "/home/abhijeet/rohan/venvs/cloud-emea-copy/lib/python3.6/site-packages/numpy/compat/__init__.py", line 12, in <module>
    from . import py3k
  File "/home/abhijeet/rohan/venvs/cloud-emea-copy/lib/python3.6/site-packages/numpy/compat/py3k.py", line 21, in <module>
    from pathlib import Path, PurePath
  File "<frozen importlib._bootstrap>", line 971, in _find_and_load
  File "<frozen importlib._bootstrap>", line 955, in _find_and_load_unlocked
  File "<frozen importlib._bootstrap>", line 665, in _load_unlocked
  File "<frozen importlib._bootstrap_external>", line 674, in exec_module
  File "<frozen importlib._bootstrap_external>", line 779, in get_code
  File "<frozen importlib._bootstrap_external>", line 487, in _compile_bytecode
KeyboardInterrupt
Command exited with non-zero status 1
0.68user 0.89system 0:00.09elapsed 1592%CPU (0avgtext+0avgdata 20000maxresident)k
0inputs+0outputs (0major+2999minor)pagefaults 0swaps
